<?xml version="1.0" ?>
<!-- =================================================================================== -->
<!-- |    This document was autogenerated by xacro from arips_arm.xacro                | -->
<!-- |    EDITING THIS FILE BY HAND IS NOT RECOMMENDED                                 | -->
<!-- =================================================================================== -->
<robot name="arips_arm" xmlns:xacro="http://ros.org/wiki/xacro">
  <material name="white">
    <color rgba="1 1 1 1"/>
  </material>
  <material name="black">
    <color rgba="0 0 0 1"/>
  </material>
  <material name="orange">
    <color rgba="1 0.6 0 1"/>
  </material>
  <link name="base_link">
    <visual>
      <geometry>
        <box size="0.05 0.05 0.01"/>
      </geometry>
      <origin xyz="0 0 0.005"/>
      <material name="black"/>
    </visual>
  </link>
  <link name="link2">
    <visual>
      <geometry>
        <cylinder length="0.07" radius="0.025"/>
      </geometry>
      <origin xyz="0 0 0.035"/>
      <material name="white"/>
    </visual>
  </link>
  <link name="link3">
    <visual>
      <geometry>
        <box size="0.02 0.05 0.12"/>
      </geometry>
      <origin xyz="0 0 0.06"/>
      <material name="white"/>
    </visual>
  </link>
  <link name="link4">
    <visual>
      <geometry>
        <box size="0.02 0.04 0.15"/>
      </geometry>
      <origin xyz="0 0 0.075"/>
      <material name="orange"/>
    </visual>
  </link>
  <link name="link5">
    <visual>
      <geometry>
        <box size="0.01 0.04 0.03"/>
      </geometry>
      <origin xyz="0 0 0"/>
      <material name="orange"/>
    </visual>
  </link>
  <link name="link6">
    <visual>
      <geometry>
        <cylinder length="0.025" radius="0.01"/>
      </geometry>
      <origin xyz="0 0 0.0125"/>
      <material name="orange"/>
    </visual>
  </link>
  <joint name="joint1" type="continuous">
    <parent link="base_link"/>
    <child link="link2"/>
    <axis xyz="0 0 1"/>
    <origin xyz="0 0 0.01"/>
  </joint>
  <joint name="joint2" type="continuous">
    <parent link="link2"/>
    <child link="link3"/>
    <axis xyz="0 1 0"/>
    <origin xyz="0 0 0.07"/>
  </joint>
  <joint name="joint3" type="continuous">
    <parent link="link3"/>
    <child link="link4"/>
    <axis xyz="0 1 0"/>
    <origin xyz="0 0 0.12"/>
  </joint>
  <joint name="joint4" type="continuous">
    <parent link="link4"/>
    <child link="link5"/>
    <axis xyz="0 1 0"/>
    <origin xyz="0 0 0.15"/>
  </joint>
  <joint name="joint5" type="continuous">
    <parent link="link5"/>
    <child link="link6"/>
    <axis xyz="0 0 1"/>
    <origin xyz="0 0 0.015"/>
  </joint>
</robot>

